Workbook

Sheet ReadMe
B2: Hybrid Zoning + Transition Optimization Engine (v7)
B3: Answers not 'what structure for the building' but 'which mass uses which strategy, in what proportions, and how systems connect'
B5: ■ Target Architecture (v7)
B6: Massing → Spatial Decomposition (L0) → Requirement Vector → Structure Allocation → Transition Detection (L5.5) → Transition Optimization → LCA → Circularity (EoL)
B7: how different systems connect, what transition members are needed, and whether the hybrid is worth its transition cost
B9: ■ Transition Engine (added in v7)
B10: L5.5 Transition: detect adjacent zones; score Structure / Geometry / Material / Load-path differences → Transition Complexity (0–100).
B11: Classify Seamless/Minor/Moderate/Complex/Critical; recommend transition members (transfer beam / belt truss / outrigger / hybrid node); estimate carbon, cost, schedule penalties.
B12: FinalScore = 0.5×Fitness + 0.3×Circularity − 0.2×TransitionPenalty
B14: ■ The nine v6 refactors (recap)
B15: 1 L0 spatial decomposition (height / core-perimeter / exposure / stress). 2 Program gives requirements
B16: 3 New requirements: Load, MEP, Lateral, position metrics. 4 Gravity & Lateral split in the genome (Int 5/5, Foam 4/3, Skin 3/4).
... B18: 7 Circularity de-duplicated → L6 only; Final = 0.7 Fitness + 0.3 Circularity (stage 1). 8 Softmax hybrid %. 9 Per-zone % output.

Sheet L0_Decomposition
B2: Level 0 Spatial Decomposition (Massing → Zones)
B4: Before program zoning, the mass is sliced into attributed zones. Each row in Allocation is one decomposed zone.
B6: 0A Height Zones | F6: 0B Core / Perimeter
B7: Band | C7: Range | D7: Example zone | F7: Zone | G7: Dist. to facade
B8: Low Rise | C8: 0–20 m | D8: Office_Low | F8: Perimeter | G8: < 6 m
B9: Mid Rise | C9: 20–60 m | D9: Office_Mid | F9: Intermediate | G9: 6–15 m
B10: High Rise | C10: 60–120 m | D10: Office_High | F10: Core | G10: >15 m
B11: Super Tall | C11: >120 m | D11: Office_Super
B13: 0D Structural Stress Zones | F13: 0C Environmental (Ladybug)
B14: Level | C14: Basis | D14: Effect | F14: Level | G14: Source
B15: High Stress | C15: moment/shear/axial/defl. high | D15: raises Load & Lateral demand | F15: High Exposure | G15: solar / wind / daylight
B16: Medium | C16: mid | F16: Medium
B17: Low | C17: low | D17: lowers Load demand | F17: Low
B19: 0A–0D attributes are written into Allocation (Program/Band/Position/Exposure/Stress) and translated into the requirement vector (L2).

Sheet L1_Programs
B2: Level 1 Program → initial requirements (Program gives requirements, NOT structure)
B4: Program no longer maps directly to a structure; it only seeds the requirement vector. Final requirements are tuned per decomposed zone (position/height/stress) in Allocation.
B6: Program | C6: Span | D6: Load | E6: MEP | F6: Adapt | G6: Lateral | H6: Modular
B7: Residential | C7: 2 | D7: 2 | E7: 2 | F7: 2 | G7: 3 | H7: 5
B8: Office | C8: 4 | D8: 3 | E8: 4 | F8: 5 | G8: 4 | H8: 5
B9: Hotel | C9: 2 | D9: 2 | E9: 3 | F9: 3 | G9: 3 | H9: 5
B10: Retail | C10: 4 | D10: 4 | E10: 3 | F10: 4 | G10: 2 | H10: 2
B11: Parking | C11: 5 | D11: 5 | E11: 2 | F11: 5 | G11: 2 | H11: 5
B12: Library | C12: 4 | D12: 5 | E12: 2 | F12: 4 | G12: 2 | H12: 2
B13: Laboratory | C13: 4 | D13: 5 | E13: 5 | F13: 5 | G13: 3 | H13: 4
B14: Healthcare | C14: 3 | D14: 4 | E14: 5 | F14: 5 | G14: 3 | H14: 4
B15: DataCenter | C15: 5 | D15: 5 | E15: 5 | F15: 2 | G15: 2 | H15: 2
B16: Conference | C16: 5 | D16: 4 | E16: 4 | F16: 4 | G16: 2 | H16: 2
B17: Warehouse | C17: 5 | D17: 5 | E17: 2 | F17: 5 | G17: 2 | H17: 3
B18: Core | C18: 1 | D18: 5 | E18: 3 | F18: 2 | G18: 5 | H18: 2
B20: ↑ Initial assumptions (0–5). Position tuning e.g.: Perimeter→Facade↑; Core→Lateral↑, Facade=0; High Stress→Load/Lateral↑.

Sheet L2_Requirements
B2: Level 2 Requirement Vector rubric (0–5)
B4: Matching evaluates Fitness/Constructability/Performance only; reuse & carbon moved to L6 to avoid double-counting (refactor #7).
B6: Span | C6: max column-free span | D6: <8m=1 | E6: 12–18m=4 | F6: >18m=5
B7: Facade Integration | C7: position: perim→high, core→0 | D7: Core=0 | E7: Inter=1-2 | F7: Perimeter=4-5
B8: Adaptability | C8: future change | D8: Housing=2 | E8: Retail=4 | F8: Office/Park=5
B9: Modular / Repetition | C9: degree of repetition | D9: Museum=1 | E9: Hotel=4 | F9: Office/Resid=5
B10: Prefab / Schedule | C10: prefab + time pressure | D10: wet trade=1 | E10: partial=3 | F10: full prefab=5
B11: Fire | C11: fire rating need | D11: garage=2 | E11: office=4 | F11: residential/assembly=5
B12: MEP Intensity (#3) | C12: services/equipment density | D12: resid/facade=1-2 | E12: office=4 | F12: lab/hospital/datacenter=5
B13: Load (#3) | C13: live+dead+occupancy | D13: Residential=2 | E13: Office=3 | F13: Park/Lib/Data=5
B14: Lateral (#3) | C14: height+wind+seismic | D14: low-rise=2 | E14: mid/high=4 | F14: super tall/core=5
B15: Cost Sensitivity | C15: budget constraint | D15: flexible=2 | E15: normal=3 | F15: tight=5
B17: Position metrics (#3): Facade Proximity / Core Proximity / Corner / Height Position → fed by L0 into the Facade/Lateral/Load demands above.

Sheet L3_Genome
B2: Level 3 Structure Genome — Fitness caps (0–5); Gravity & Lateral split (#4)
B4: Holds Fitness/Constructability/Performance capacities only (carbon & reuse moved to L6). Gravity and Lateral capacities are evaluated separately (#4).
B5: Structure | C5: Span | D5: Facade | E5: Adapt | F5: Modular | G5: Prefab | H5: Fire | I5: MEP | J5: Gravity | K5: Lateral | L5: Cost-E | M5: Typical systems | N5: Calibration basis (Sources)
B6: Structural Skin | C6: 2 | D6: 5 | E6: 4 | F6: 4 | G6: 5 | H6: 3 | I6: 3 | J6: 3 | K6: 4 | L6: 2 | M6: Diagrid / Exoskeleton / Timber Shell | N6: Gravity 3: perimeter system, interior spans rely on floor; Lateral 4: diagrid high stiffness (super-tall cases); Facade 5; Prefab 5; MEP 3: perimeter doesn't block interior services.
B7: Structural Foam | C7: 3 | D7: 2 | E7: 5 | F7: 5 | G7: 5 | H7: 4 | I7: 2 | J7: 4 | K7: 3 | L7: 3 | M7: CLT Cellular / Voronoi / Space Frame | N7: Gravity 4; Lateral 3: light but not a primary lateral system, limited super-tall (constraint multiplier); Modular 5 / Prefab 5; MEP 2: solid timber beams hard to penetrate.
B8: Internal Structure | C8: 5 | D8: 1 | E8: 3 | F8: 3 | G8: 3 | H8: 5 | I8: 5 | J8: 5 | K8: 5 | L8: 4 | M8: Steel / Concrete Frame / Core+Frame | N8: Gravity 5 / Lateral 5: core+frame is the super-tall standard; long span 5; Fire 5; MEP 5: cellular beams let services pass through to protect clear height.

Sheet L6_Circularity
B2: Level 6 Circularity / Post-End-of-Life (0.3 of final score, #7)
B4: Weights (sum=1)
D5: Reuse Potential | E5: Disassembly | F5: Material Recovery | G5: Carbon Storage
B6: Weights → | D6: 0.25 | E6: 0.25 | F6: 0.25 | G6: 0.25
B8: Structure base scores (0–100, editable)
B9: Structure | C9: Reuse Potential | D9: Disassembly | E9: Material Recovery | F9: Carbon Storage
B10: Structural Skin | C10: 80 | D10: 90 | E10: 90 | F10: 60 | I10: Bolted dry joints demountable; steel direct reuse ~7%; timber shell stores carbon → 60
B11: Structural Foam | C11: 85 | D11: 92 | E11: 85 | F11: 85 | I11: Modular bolted, easy to disassemble; CLT stores biogenic carbon → 85
B12: Internal Structure | C12: 25 | D12: 25 | E12: 65 | F12: 5 | I12: Cast-in-place not demountable; steel recycled but direct reuse ~7%; no biogenic carbon → 5
B14: Composite (=Σ metric×weight)
B15: =B10 -> Structural Skin | C15: =SUMPRODUCT(C10:F10,$D$6:$G$6) -> 80
B16: =B11 -> Structural Foam | C16: =SUMPRODUCT(C11:F11,$D$6:$G$6) -> 86.75
B17: =B12 -> Internal Structure | C17: =SUMPRODUCT(C12:F12,$D$6:$G$6) -> 30

Sheet L4_Multipliers
B2: Level 4 Multipliers (replace additive bonuses, cap 1.25, #5/#6)
B5: Condition | C5: Multiplier | D5: Rationale
B6: Span(m) > 18 | C6: Internal ×1.15 | D6: large span favors steel/RC frame
B7: Facade demand > 4 | C7: Skin ×1.15 | D7: high facade integration → skin
B8: Lateral demand = 5 | C8: Internal ×1.10 / Skin ×1.05 / Foam ×0.85 | D8: lateral: core or diagrid good, Foam weak
B9: MEP demand = 5 | C9: Internal ×1.10 / Foam ×0.90 | D9: cellular beams pass services; solid beams eat clear height
B10: Load demand = 5 | C10: Internal ×1.10 | D10: heavy loads favor frames
B11: Height(m) > 120 (constraint #6) | C11: Foam ×0.70 / Skin ×1.05 | D11: timber not a super-tall primary; diagrid good
B12: Cap | C12: each system multiplier clamped 0.6–1.25 | D12: prevents any single factor dominating base score
B14: Height counted once (#6): height enters the Lateral demand (vector); >120m is only a constraint multiplier, not a bonus.

Sheet Allocation
A1: Hybrid Allocation Engine ★ each decomposed zone → Skin/Foam/Internal percentages
B2: Softmax T | C2: 8 | D2: Fit wt | E2: 0.7 | F2: Circ wt | G2: =1-E2 -> 0.3 | I2: Circ→ | J2: =L6_Circularity!$C$15 -> 80 | K2: =L6_Circularity!$C$16 -> 86.75 | L2: =L6_Circularity!$C$17 -> 30
A3: Zone (spatial decomposition) | H3: Requirement vector (0–5) | R3: Geometry | T3: Fitness % | W3: Multiplier | Z3: Final | AC3: Allocation % | AF3: Lead
A4: ID | B4: Zone | C4: Prog | D4: Band | E4: Pos | F4: Expo | G4: Stress | H4: Span | I4: Faç | J4: Adpt | K4: Mod | L4: Pref | M4: Fire | N4: MEP | O4: Load | P4: Lat | Q4: Cost | R4: H(m) | S4: Sp(m) | T4: Skin | U4: Foam | V4: Intl | W4: Skin | X4: Foam | Y4: Intl | Z4: Skin | AA4: Foam | AB4: Intl | AC4: Skin% | AD4: Foam% | AE4: Intl% | AF4: Primary | AG4: Top% | AH4: Lead
A5: 1 | B5: Retail Lo Perim | C5: Retail | D5: Low | E5: Perim | F5: High | G5: Med | H5: 4 | I5: 3 | J5: 4 | K5: 2 | L5: 2 | M5: 4 | N5: 3 | O5: 4 | P5: 2 | Q5: 3 | R5: 10 | S5: 18 | T5: =SUMPRODUCT($H5:$Q5,L3_Genome!$C$6:$L$6)/(SUM($H5:$Q5)*5)*100 -> 67.096774 | U5: =SUMPRODUCT($H5:$Q5,L3_Genome!$C$7:$L$7)/(SUM($H5:$Q5)*5)*100 -> 71.612903 | V5: =SUMPRODUCT($H5:$Q5,L3_Genome!$C$8:$L$8)/(SUM($H5:$Q5)*5)*100 -> 80 | W5: =MAX(0.6,MIN(1.25,IF($I5>4,1.15,1)*IF($P5=5,1.05,1)*IF($R5>120,1.05,1))) -> 1 | X5: =MAX(0.6,MIN(1.25,IF($N5=5,0.9,1)*IF($P5=5,0.85,1)*IF($R5>120,0.7,1))) -> 1 | Y5: =MAX(0.6,MIN(1.25,IF($S5>18,1.15,1)*IF($N5=5,1.1,1)*IF($P5=5,1.1,1)*IF($O5=5,1.1,1))) -> 1 | Z5: =$E$2*(T5*W5)+$G$2*$J$2 -> 70.967742 | AA5: =$E$2*(U5*X5)+$G$2*$K$2 -> 76.154032 | AB5: =$E$2*(V5*Y5)+$G$2*$L$2 -> 65 | AC5: =EXP(Z5/$C$2)/(EXP(Z5/$C$2)+EXP(AA5/$C$2)+EXP(AB5/$C$2)) -> 0.29528698 | AD5: =EXP(AA5/$C$2)/(EXP(Z5/$C$2)+EXP(AA5/$C$2)+EXP(AB5/$C$2)) -> 0.56466576 | AE5: =EXP(AB5/$C$2)/(EXP(Z5/$C$2)+EXP(AA5/$C$2)+EXP(AB5/$C$2)) -> 0.14004726 | AF5: =IF(AND(AC5>=AD5,AC5>=AE5),"Skin",IF(AD5>=AE5,"Foam","Internal")) -> Foam | AG5: =MAX(AC5:AE5) -> 0.56466576 | AH5: =MAX(AC5:AE5)-LARGE(AC5:AE5,2) -> 0.26937878
A6: 2 | B6: Retail Lo Core | C6: Retail | D6: Low | E6: Core | F6: Low | G6: High | H6: 5 | I6: 0 | J6: 4 | K6: 2 | L6: 2 | M6: 4 | N6: 3 | O6: 5 | P6: 2 | Q6: 3 | R6: 10 | S6: 20 | T6: =SUMPRODUCT($H6:$Q6,L3_Genome!$C$6:$L$6)/(SUM($H6:$Q6)*5)*100 -> 62.666667 | U6: =SUMPRODUCT($H6:$Q6,L3_Genome!$C$7:$L$7)/(SUM($H6:$Q6)*5)*100 -> 74.666667 | V6: =SUMPRODUCT($H6:$Q6,L3_Genome!$C$8:$L$8)/(SUM($H6:$Q6)*5)*100 -> 87.333333 | W6: =MAX(0.6,MIN(1.25,IF($I6>4,1.15,1)*IF($P6=5,1.05,1)*IF($R6>120,1.05,1))) -> 1 | X6: =MAX(0.6,MIN(1.25,IF($N6=5,0.9,1)*IF($P6=5,0.85,1)*IF($R6>120,0.7,1))) -> 1 | Y6: =MAX(0.6,MIN(1.25,IF($S6>18,1.15,1)*IF($N6=5,1.1,1)*IF($P6=5,1.1,1)*IF($O6=5,1.1,1))) -> 1.25 | Z6: =$E$2*(T6*W6)+$G$2*$J$2 -> 67.866667 | AA6: =$E$2*(U6*X6)+$G$2*$K$2 -> 78.291667 | AB6: =$E$2*(V6*Y6)+$G$2*$L$2 -> 85.416667 | AC6: =EXP(Z6/$C$2)/(EXP(Z6/$C$2)+EXP(AA6/$C$2)+EXP(AB6/$C$2)) -> 0.073262412 | AD6: =EXP(AA6/$C$2)/(EXP(Z6/$C$2)+EXP(AA6/$C$2)+EXP(AB6/$C$2)) -> 0.26966291 | AE6: =EXP(AB6/$C$2)/(EXP(Z6/$C$2)+EXP(AA6/$C$2)+EXP(AB6/$C$2)) -> 0.65707468 | AF6: =IF(AND(AC6>=AD6,AC6>=AE6),"Skin",IF(AD6>=AE6,"Foam","Internal")) -> Internal | AG6: =MAX(AC6:AE6) -> 0.65707468 | AH6: =MAX(AC6:AE6)-LARGE(AC6:AE6,2) -> 0.38741178
A7: 3 | B7: Lobby Lo | C7: Lobby | D7: Low | E7: Perim | F7: High | G7: Med | H7: 5 | I7: 4 | J7: 3 | K7: 1 | L7: 2 | M7: 4 | N7: 2 | O7: 3 | P7: 2 | Q7: 3 | R7: 12 | S7: 22 | T7: =SUMPRODUCT($H7:$Q7,L3_Genome!$C$6:$L$6)/(SUM($H7:$Q7)*5)*100 -> 66.896552 | U7: =SUMPRODUCT($H7:$Q7,L3_Genome!$C$7:$L$7)/(SUM($H7:$Q7)*5)*100 -> 68.965517 | V7: =SUMPRODUCT($H7:$Q7,L3_Genome!$C$8:$L$8)/(SUM($H7:$Q7)*5)*100 -> 78.62069 | W7: =MAX(0.6,MIN(1.25,IF($I7>4,1.15,1)*IF($P7=5,1.05,1)*IF($R7>120,1.05,1))) -> 1 | X7: =MAX(0.6,MIN(1.25,IF($N7=5,0.9,1)*IF($P7=5,0.85,1)*IF($R7>120,0.7,1))) -> 1 | Y7: =MAX(0.6,MIN(1.25,IF($S7>18,1.15,1)*IF($N7=5,1.1,1)*IF($P7=5,1.1,1)*IF($O7=5,1.1,1))) -> 1.15 | Z7: =$E$2*(T7*W7)+$G$2*$J$2 -> 70.827586 | AA7: =$E$2*(U7*X7)+$G$2*$K$2 -> 74.300862 | AB7: =$E$2*(V7*Y7)+$G$2*$L$2 -> 72.289655 | AC7: =EXP(Z7/$C$2)/(EXP(Z7/$C$2)+EXP(AA7/$C$2)+EXP(AB7/$C$2)) -> 0.26708049 | AD7: =EXP(AA7/$C$2)/(EXP(Z7/$C$2)+EXP(AA7/$C$2)+EXP(AB7/$C$2)) -> 0.41228281 | AE7: =EXP(AB7/$C$2)/(EXP(Z7/$C$2)+EXP(AA7/$C$2)+EXP(AB7/$C$2)) -> 0.3206367 | AF7: =IF(AND(AC7>=AD7,AC7>=AE7),"Skin",IF(AD7>=AE7,"Foam","Internal")) -> Foam | AG7: =MAX(AC7:AE7) -> 0.41228281 | AH7: =MAX(AC7:AE7)-LARGE(AC7:AE7,2) -> 0.091646118
A8: 4 | B8: Parking Lo | C8: Parking | D8: Low | E8: Core | F8: Low | G8: Med | H8: 5 | I8: 1 | J8: 5 | K8: 5 | L8: 4 | M8: 4 | N8: 2 | O8: 5 | P8: 2 | Q8: 4 | R8: 8 | S8: 16 | T8: =SUMPRODUCT($H8:$Q8,L3_Genome!$C$6:$L$6)/(SUM($H8:$Q8)*5)*100 -> 67.027027 | U8: =SUMPRODUCT($H8:$Q8,L3_Genome!$C$7:$L$7)/(SUM($H8:$Q8)*5)*100 -> 78.378378 | V8: =SUMPRODUCT($H8:$Q8,L3_Genome!$C$8:$L$8)/(SUM($H8:$Q8)*5)*100 -> 80.540541 | W8: =MAX(0.6,MIN(1.25,IF($I8>4,1.15,1)*IF($P8=5,1.05,1)*IF($R8>120,1.05,1))) -> 1 | X8: =MAX(0.6,MIN(1.25,IF($N8=5,0.9,1)*IF($P8=5,0.85,1)*IF($R8>120,0.7,1))) -> 1 | Y8: =MAX(0.6,MIN(1.25,IF($S8>18,1.15,1)*IF($N8=5,1.1,1)*IF($P8=5,1.1,1)*IF($O8=5,1.1,1))) -> 1.1 | Z8: =$E$2*(T8*W8)+$G$2*$J$2 -> 70.918919 | AA8: =$E$2*(U8*X8)+$G$2*$K$2 -> 80.889865 | AB8: =$E$2*(V8*Y8)+$G$2*$L$2 -> 71.016216 | AC8: =EXP(Z8/$C$2)/(EXP(Z8/$C$2)+EXP(AA8/$C$2)+EXP(AB8/$C$2)) -> 0.18215181 | AD8: =EXP(AA8/$C$2)/(EXP(Z8/$C$2)+EXP(AA8/$C$2)+EXP(AB8/$C$2)) -> 0.6334675 | AE8: =EXP(AB8/$C$2)/(EXP(Z8/$C$2)+EXP(AA8/$C$2)+EXP(AB8/$C$2)) -> 0.18438069 | AF8: =IF(AND(AC8>=AD8,AC8>=AE8),"Skin",IF(AD8>=AE8,"Foam","Internal")) -> Foam | AG8: =MAX(AC8:AE8) -> 0.6334675 | AH8: =MAX(AC8:AE8)-LARGE(AC8:AE8,2) -> 0.4490868
A9: 5 | B9: Conference Lo | C9: Conference | D9: Low | E9: Core | F9: Low | G9: High | H9: 5 | I9: 2 | J9: 4 | K9: 2 | L9: 3 | M9: 5 | N9: 4 | O9: 4 | P9: 2 | Q9: 3 | R9: 12 | S9: 24 | T9: =SUMPRODUCT($H9:$Q9,L3_Genome!$C$6:$L$6)/(SUM($H9:$Q9)*5)*100 -> 65.882353 | U9: =SUMPRODUCT($H9:$Q9,L3_Genome!$C$7:$L$7)/(SUM($H9:$Q9)*5)*100 -> 72.352941 | V9: =SUMPRODUCT($H9:$Q9,L3_Genome!$C$8:$L$8)/(SUM($H9:$Q9)*5)*100 -> 82.941176 | W9: =MAX(0.6,MIN(1.25,IF($I9>4,1.15,1)*IF($P9=5,1.05,1)*IF($R9>120,1.05,1))) -> 1 | X9: =MAX(0.6,MIN(1.25,IF($N9=5,0.9,1)*IF($P9=5,0.85,1)*IF($R9>120,0.7,1))) -> 1 | Y9: =MAX(0.6,MIN(1.25,IF($S9>18,1.15,1)*IF($N9=5,1.1,1)*IF($P9=5,1.1,1)*IF($O9=5,1.1,1))) -> 1.15 | Z9: =$E$2*(T9*W9)+$G$2*$J$2 -> 70.117647 | AA9: =$E$2*(U9*X9)+$G$2*$K$2 -> 76.672059 | AB9: =$E$2*(V9*Y9)+$G$2*$L$2 -> 75.767647 | AC9: =EXP(Z9/$C$2)/(EXP(Z9/$C$2)+EXP(AA9/$C$2)+EXP(AB9/$C$2)) -> 0.18884698 | AD9: =EXP(AA9/$C$2)/(EXP(Z9/$C$2)+EXP(AA9/$C$2)+EXP(AB9/$C$2)) -> 0.42847763 | AE9: =EXP(AB9/$C$2)/(EXP(Z9/$C$2)+EXP(AA9/$C$2)+EXP(AB9/$C$2)) -> 0.38267538 | AF9: =IF(AND(AC9>=AD9,AC9>=AE9),"Skin",IF(AD9>=AE9,"Foam","Internal")) -> Foam | AG9: =MAX(AC9:AE9) -> 0.42847763 | AH9: =MAX(AC9:AE9)-LARGE(AC9:AE9,2) -> 0.045802249
A10: 6 | B10: DataCenter Lo | C10: DataCenter | D10: Low | E10: Core | F10: Low | G10: High | H10: 5 | I10: 1 | J10: 2 | K10: 2 | L10: 3 | M10: 5 | N10: 5 | O10: 5 | P10: 2 | Q10: 4 | R10: 10 | S10: 14 | T10: =SUMPRODUCT($H10:$Q10,L3_Genome!$C$6:$L$6)/(SUM($H10:$Q10)*5)*100 -> 62.941176 | U10: =SUMPRODUCT($H10:$Q10,L3_Genome!$C$7:$L$7)/(SUM($H10:$Q10)*5)*100 -> 70.588235 | V10: =SUMPRODUCT($H10:$Q10,L3_Genome!$C$8:$L$8)/(SUM($H10:$Q10)*5)*100 -> 87.058824 | W10: =MAX(0.6,MIN(1.25,IF($I10>4,1.15,1)*IF($P10=5,1.05,1)*IF($R10>120,1.05,1))) -> 1 | X10: =MAX(0.6,MIN(1.25,IF($N10=5,0.9,1)*IF($P10=5,0.85,1)*IF($R10>120,0.7,1))) -> 0.9 | Y10: =MAX(0.6,MIN(1.25,IF($S10>18,1.15,1)*IF($N10=5,1.1,1)*IF($P10=5,1.1,1)*IF($O10=5,1.1,1))) -> 1.21 | Z10: =$E$2*(T10*W10)+$G$2*$J$2 -> 68.058824 | AA10: =$E$2*(U10*X10)+$G$2*$K$2 -> 70.495588 | AB10: =$E$2*(V10*Y10)+$G$2*$L$2 -> 82.738824 | AC10: =EXP(Z10/$C$2)/(EXP(Z10/$C$2)+EXP(AA10/$C$2)+EXP(AB10/$C$2)) -> 0.11599299 | AD10: =EXP(AA10/$C$2)/(EXP(Z10/$C$2)+EXP(AA10/$C$2)+EXP(AB10/$C$2)) -> 0.15729537 | AE10: =EXP(AB10/$C$2)/(EXP(Z10/$C$2)+EXP(AA10/$C$2)+EXP(AB10/$C$2)) -> 0.72671164 | AF10: =IF(AND(AC10>=AD10,AC10>=AE10),"Skin",IF(AD10>=AE10,"Foam","Internal")) -> Internal | AG10: =MAX(AC10:AE10) -> 0.72671164 | AH10: =MAX(AC10:AE10)-LARGE(AC10:AE10,2) -> 0.56941628
A11: 7 | B11: Office Mid S-Perim | C11: Office | D11: Mid | E11: Perim | F11: High | G11: Med | H11: 4 | I11: 5 | J11: 5 | K11: 5 | L11: 4 | M11: 4 | N11: 3 | O11: 3 | P11: 4 | Q11: 3 | R11: 45 | S11: 12 | T11: =SUMPRODUCT($H11:$Q11,L3_Genome!$C$6:$L$6)/(SUM($H11:$Q11)*5)*100 -> 72.5 | U11: =SUMPRODUCT($H11:$Q11,L3_Genome!$C$7:$L$7)/(SUM($H11:$Q11)*5)*100 -> 73.5 | V11: =SUMPRODUCT($H11:$Q11,L3_Genome!$C$8:$L$8)/(SUM($H11:$Q11)*5)*100 -> 74.5 | W11: =MAX(0.6,MIN(1.25,IF($I11>4,1.15,1)*IF($P11=5,1.05,1)*IF($R11>120,1.05,1))) -> 1.15 | X11: =MAX(0.6,MIN(1.25,IF($N11=5,0.9,1)*IF($P11=5,0.85,1)*IF($R11>120,0.7,1))) -> 1 | Y11: =MAX(0.6,MIN(1.25,IF($S11>18,1.15,1)*IF($N11=5,1.1,1)*IF($P11=5,1.1,1)*IF($O11=5,1.1,1))) -> 1 | Z11: =$E$2*(T11*W11)+$G$2*$J$2 -> 82.3625 | AA11: =$E$2*(U11*X11)+$G$2*$K$2 -> 77.475 | AB11: =$E$2*(V11*Y11)+$G$2*$L$2 -> 61.15 | AC11: =EXP(Z11/$C$2)/(EXP(Z11/$C$2)+EXP(AA11/$C$2)+EXP(AB11/$C$2)) -> 0.61981577 | AD11: =EXP(AA11/$C$2)/(EXP(Z11/$C$2)+EXP(AA11/$C$2)+EXP(AB11/$C$2)) -> 0.33646186 | AE11: =EXP(AB11/$C$2)/(EXP(Z11/$C$2)+EXP(AA11/$C$2)+EXP(AB11/$C$2)) -> 0.043722367 | AF11: =IF(AND(AC11>=AD11,AC11>=AE11),"Skin",IF(AD11>=AE11,"Foam","Internal")) -> Skin | AG11: =MAX(AC11:AE11) -> 0.61981577 | AH11: =MAX(AC11:AE11)-LARGE(AC11:AE11,2) -> 0.28335392
A12: 8 | B12: Office Mid Core | C12: Office | D12: Mid | E12: Core | F12: Low | G12: High | H12: 3 | I12: 0 | J12: 4 | K12: 4 | L12: 3 | M12: 5 | N12: 4 | O12: 4 | P12: 5 | Q12: 3 | R12: 45 | S12: 10 | T12: =SUMPRODUCT($H12:$Q12,L3_Genome!$C$6:$L$6)/(SUM($H12:$Q12)*5)*100 -> 67.428571 | U12: =SUMPRODUCT($H12:$Q12,L3_Genome!$C$7:$L$7)/(SUM($H12:$Q12)*5)*100 -> 75.428571 | V12: =SUMPRODUCT($H12:$Q12,L3_Genome!$C$8:$L$8)/(SUM($H12:$Q12)*5)*100 -> 85.714286 | W12: =MAX(0.6,MIN(1.25,IF($I12>4,1.15,1)*IF($P12=5,1.05,1)*IF($R12>120,1.05,1))) -> 1.05 | X12: =MAX(0.6,MIN(1.25,IF($N12=5,0.9,1)*IF($P12=5,0.85,1)*IF($R12>120,0.7,1))) -> 0.85 | Y12: =MAX(0.6,MIN(1.25,IF($S12>18,1.15,1)*IF($N12=5,1.1,1)*IF($P12=5,1.1,1)*IF($O12=5,1.1,1))) -> 1.1 | Z12: =$E$2*(T12*W12)+$G$2*$J$2 -> 73.56 | AA12: =$E$2*(U12*X12)+$G$2*$K$2 -> 70.905 | AB12: =$E$2*(V12*Y12)+$G$2*$L$2 -> 75 | AC12: =EXP(Z12/$C$2)/(EXP(Z12/$C$2)+EXP(AA12/$C$2)+EXP(AB12/$C$2)) -> 0.34307737 | AD12: =EXP(AA12/$C$2)/(EXP(Z12/$C$2)+EXP(AA12/$C$2)+EXP(AB12/$C$2)) -> 0.24618444 | AE12: =EXP(AB12/$C$2)/(EXP(Z12/$C$2)+EXP(AA12/$C$2)+EXP(AB12/$C$2)) -> 0.41073819 | AF12: =IF(AND(AC12>=AD12,AC12>=AE12),"Skin",IF(AD12>=AE12,"Foam","Internal")) -> Internal | AG12: =MAX(AC12:AE12) -> 0.41073819 | AH12: =MAX(AC12:AE12)-LARGE(AC12:AE12,2) -> 0.067660815
A13: 9 | B13: Office Mid N-Perim | C13: Office | D13: Mid | E13: Perim | F13: Med | G13: Low | H13: 4 | I13: 3 | J13: 5 | K13: 5 | L13: 4 | M13: 4 | N13: 3 | O13: 3 | P13: 3 | Q13: 3 | R13: 45 | S13: 12 | T13: =SUMPRODUCT($H13:$Q13,L3_Genome!$C$6:$L$6)/(SUM($H13:$Q13)*5)*100 -> 70.810811 | U13: =SUMPRODUCT($H13:$Q13,L3_Genome!$C$7:$L$7)/(SUM($H13:$Q13)*5)*100 -> 75.675676 | V13: =SUMPRODUCT($H13:$Q13,L3_Genome!$C$8:$L$8)/(SUM($H13:$Q13)*5)*100 -> 76.756757 | W13: =MAX(0.6,MIN(1.25,IF($I13>4,1.15,1)*IF($P13=5,1.05,1)*IF($R13>120,1.05,1))) -> 1 | X13: =MAX(0.6,MIN(1.25,IF($N13=5,0.9,1)*IF($P13=5,0.85,1)*IF($R13>120,0.7,1))) -> 1 | Y13: =MAX(0.6,MIN(1.25,IF($S13>18,1.15,1)*IF($N13=5,1.1,1)*IF($P13=5,1.1,1)*IF($O13=5,1.1,1))) -> 1 | Z13: =$E$2*(T13*W13)+$G$2*$J$2 -> 73.567568 | AA13: =$E$2*(U13*X13)+$G$2*$K$2 -> 78.997973 | AB13: =$E$2*(V13*Y13)+$G$2*$L$2 -> 62.72973 | AC13: =EXP(Z13/$C$2)/(EXP(Z13/$C$2)+EXP(AA13/$C$2)+EXP(AB13/$C$2)) -> 0.30964269 | AD13: =EXP(AA13/$C$2)/(EXP(Z13/$C$2)+EXP(AA13/$C$2)+EXP(AB13/$C$2)) -> 0.61046423 | AE13: =EXP(AB13/$C$2)/(EXP(Z13/$C$2)+EXP(AA13/$C$2)+EXP(AB13/$C$2)) -> 0.079893084 | AF13: =IF(AND(AC13>=AD13,AC13>=AE13),"Skin",IF(AD13>=AE13,"Foam","Internal")) -> Foam | AG13: =MAX(AC13:AE13) -> 0.61046423 | AH13: =MAX(AC13:AE13)-LARGE(AC13:AE13,2) -> 0.30082154
A14: 10 | B14: Hotel Mid Perim | C14: Hotel | D14: Mid | E14: Perim | F14: Med | G14: Low | H14: 2 | I14: 3 | J14: 3 | K14: 5 | L14: 5 | M14: 5 | N14: 3 | O14: 2 | P14: 3 | Q14: 3 | R14: 50 | S14: 9 | T14: =SUMPRODUCT($H14:$Q14,L3_Genome!$C$6:$L$6)/(SUM($H14:$Q14)*5)*100 -> 72.941176 | U14: =SUMPRODUCT($H14:$Q14,L3_Genome!$C$7:$L$7)/(SUM($H14:$Q14)*5)*100 -> 75.882353 | V14: =SUMPRODUCT($H14:$Q14,L3_Genome!$C$8:$L$8)/(SUM($H14:$Q14)*5)*100 -> 75.882353 | W14: =MAX(0.6,MIN(1.25,IF($I14>4,1.15,1)*IF($P14=5,1.05,1)*IF($R14>120,1.05,1))) -> 1 | X14: =MAX(0.6,MIN(1.25,IF($N14=5,0.9,1)*IF($P14=5,0.85,1)*IF($R14>120,0.7,1))) -> 1 | Y14: =MAX(0.6,MIN(1.25,IF($S14>18,1.15,1)*IF($N14=5,1.1,1)*IF($P14=5,1.1,1)*IF($O14=5,1.1,1))) -> 1 | Z14: =$E$2*(T14*W14)+$G$2*$J$2 -> 75.058824 | AA14: =$E$2*(U14*X14)+$G$2*$K$2 -> 79.142647 | AB14: =$E$2*(V14*Y14)+$G$2*$L$2 -> 62.117647 | AC14: =EXP(Z14/$C$2)/(EXP(Z14/$C$2)+EXP(AA14/$C$2)+EXP(AB14/$C$2)) -> 0.34910689 | AD14: =EXP(AA14/$C$2)/(EXP(Z14/$C$2)+EXP(AA14/$C$2)+EXP(AB14/$C$2)) -> 0.58164256 | AE14: =EXP(AB14/$C$2)/(EXP(Z14/$C$2)+EXP(AA14/$C$2)+EXP(AB14/$C$2)) -> 0.069250551 | AF14: =IF(AND(AC14>=AD14,AC14>=AE14),"Skin",IF(AD14>=AE14,"Foam","Internal")) -> Foam | AG14: =MAX(AC14:AE14) -> 0.58164256 | AH14: =MAX(AC14:AE14)-LARGE(AC14:AE14,2) -> 0.23253567
A15: 11 | B15: Lab Mid | C15: Laboratory | D15: Mid | E15: Inter | F15: Med | G15: High | H15: 4 | I15: 2 | J15: 5 | K15: 4 | L15: 3 | M15: 5 | N15: 5 | O15: 5 | P15: 3 | Q15: 3 | R15: 40 | S15: 12 | T15: =SUMPRODUCT($H15:$Q15,L3_Genome!$C$6:$L$6)/(SUM($H15:$Q15)*5)*100 -> 67.692308 | U15: =SUMPRODUCT($H15:$Q15,L3_Genome!$C$7:$L$7)/(SUM($H15:$Q15)*5)*100 -> 73.846154 | V15: =SUMPRODUCT($H15:$Q15,L3_Genome!$C$8:$L$8)/(SUM($H15:$Q15)*5)*100 -> 82.051282 | W15: =MAX(0.6,MIN(1.25,IF($I15>4,1.15,1)*IF($P15=5,1.05,1)*IF($R15>120,1.05,1))) -> 1 | X15: =MAX(0.6,MIN(1.25,IF($N15=5,0.9,1)*IF($P15=5,0.85,1)*IF($R15>120,0.7,1))) -> 0.9 | Y15: =MAX(0.6,MIN(1.25,IF($S15>18,1.15,1)*IF($N15=5,1.1,1)*IF($P15=5,1.1,1)*IF($O15=5,1.1,1))) -> 1.21 | Z15: =$E$2*(T15*W15)+$G$2*$J$2 -> 71.384615 | AA15: =$E$2*(U15*X15)+$G$2*$K$2 -> 72.548077 | AB15: =$E$2*(V15*Y15)+$G$2*$L$2 -> 78.497436 | AC15: =EXP(Z15/$C$2)/(EXP(Z15/$C$2)+EXP(AA15/$C$2)+EXP(AB15/$C$2)) -> 0.21788936 | AD15: =EXP(AA15/$C$2)/(EXP(Z15/$C$2)+EXP(AA15/$C$2)+EXP(AB15/$C$2)) -> 0.25199774 | AE15: =EXP(AB15/$C$2)/(EXP(Z15/$C$2)+EXP(AA15/$C$2)+EXP(AB15/$C$2)) -> 0.5301129 | AF15: =IF(AND(AC15>=AD15,AC15>=AE15),"Skin",IF(AD15>=AE15,"Foam","Internal")) -> Internal | AG15: =MAX(AC15:AE15) -> 0.5301129 | AH15: =MAX(AC15:AE15)-LARGE(AC15:AE15,2) -> 0.27811515
A16: 12 | B16: Office Hi S-Perim | C16: Office | D16: High | E16: Perim | F16: High | G16: Med | H16: 4 | I16: 5 | J16: 5 | K16: 5 | L16: 4 | M16: 4 | N16: 3 | O16: 3 | P16: 5 | Q16: 3 | R16: 90 | S16: 12 | T16: =SUMPRODUCT($H16:$Q16,L3_Genome!$C$6:$L$6)/(SUM($H16:$Q16)*5)*100 -> 72.682927 | U16: =SUMPRODUCT($H16:$Q16,L3_Genome!$C$7:$L$7)/(SUM($H16:$Q16)*5)*100 -> 73.170732 | V16: =SUMPRODUCT($H16:$Q16,L3_Genome!$C$8:$L$8)/(SUM($H16:$Q16)*5)*100 -> 75.121951 | W16: =MAX(0.6,MIN(1.25,IF($I16>4,1.15,1)*IF($P16=5,1.05,1)*IF($R16>120,1.05,1))) -> 1.2075 | X16: =MAX(0.6,MIN(1.25,IF($N16=5,0.9,1)*IF($P16=5,0.85,1)*IF($R16>120,0.7,1))) -> 0.85 | Y16: =MAX(0.6,MIN(1.25,IF($S16>18,1.15,1)*IF($N16=5,1.1,1)*IF($P16=5,1.1,1)*IF($O16=5,1.1,1))) -> 1.1 | Z16: =$E$2*(T16*W16)+$G$2*$J$2 -> 85.435244 | AA16: =$E$2*(U16*X16)+$G$2*$K$2 -> 69.561585 | AB16: =$E$2*(V16*Y16)+$G$2*$L$2 -> 66.843902 | AC16: =EXP(Z16/$C$2)/(EXP(Z16/$C$2)+EXP(AA16/$C$2)+EXP(AB16/$C$2)) -> 0.80946826 | AD16: =EXP(AA16/$C$2)/(EXP(Z16/$C$2)+EXP(AA16/$C$2)+EXP(AB16/$C$2)) -> 0.11129343 | AE16: =EXP(AB16/$C$2)/(EXP(Z16/$C$2)+EXP(AA16/$C$2)+EXP(AB16/$C$2)) -> 0.079238309 | AF16: =IF(AND(AC16>=AD16,AC16>=AE16),"Skin",IF(AD16>=AE16,"Foam","Internal")) -> Skin | AG16: =MAX(AC16:AE16) -> 0.80946826 | AH16: =MAX(AC16:AE16)-LARGE(AC16:AE16,2) -> 0.69817483
... A30: 26 | B30: Healthcare Mid | C30: Healthcare | D30: Mid | E30: Inter | F30: Med | G30: High | H30: 3 | I30: 2 | J30: 5 | K30: 4 | L30: 4 | M30: 5 | N30: 5 | O30: 4 | P30: 3 | Q30: 3 | R30: 50 | S30: 10 | T30: =SUMPRODUCT($H30:$Q30,L3_Genome!$C$6:$L$6)/(SUM($H30:$Q30)*5)*100 -> 69.473684 | U30: =SUMPRODUCT($H30:$Q30,L3_Genome!$C$7:$L$7)/(SUM($H30:$Q30)*5)*100 -> 74.736842 | V30: =SUMPRODUCT($H30:$Q30,L3_Genome!$C$8:$L$8)/(SUM($H30:$Q30)*5)*100 -> 80.526316 | W30: =MAX(0.6,MIN(1.25,IF($I30>4,1.15,1)*IF($P30=5,1.05,1)*IF($R30>120,1.05,1))) -> 1 | X30: =MAX(0.6,MIN(1.25,IF($N30=5,0.9,1)*IF($P30=5,0.85,1)*IF($R30>120,0.7,1))) -> 0.9 | Y30: =MAX(0.6,MIN(1.25,IF($S30>18,1.15,1)*IF($N30=5,1.1,1)*IF($P30=5,1.1,1)*IF($O30=5,1.1,1))) -> 1.1 | Z30: =$E$2*(T30*W30)+$G$2*$J$2 -> 72.631579 | AA30: =$E$2*(U30*X30)+$G$2*$K$2 -> 73.109211 | AB30: =$E$2*(V30*Y30)+$G$2*$L$2 -> 71.005263 | AC30: =EXP(Z30/$C$2)/(EXP(Z30/$C$2)+EXP(AA30/$C$2)+EXP(AB30/$C$2)) -> 0.34751614 | AD30: =EXP(AA30/$C$2)/(EXP(Z30/$C$2)+EXP(AA30/$C$2)+EXP(AB30/$C$2)) -> 0.36889611 | AE30: =EXP(AB30/$C$2)/(EXP(Z30/$C$2)+EXP(AA30/$C$2)+EXP(AB30/$C$2)) -> 0.28358776 | AF30: =IF(AND(AC30>=AD30,AC30>=AE30),"Skin",IF(AD30>=AE30,"Foam","Internal")) -> Foam | AG30: =MAX(AC30:AE30) -> 0.36889611 | AH30: =MAX(AC30:AE30)-LARGE(AC30:AE30,2) -> 0.021379969
A32: Stage 1: Final = 0.7×(Fitness%×Multiplier) + 0.3×Circularity → Softmax(/T) → %. Stage 2 on 'Transition_Engine': add adjacency penalty, Final = 0.5×Fitness + 0.3×Circularity − 0.2×Transition. Multiplier cap 1.25; >120m is a Foam constraint (×0.7).

Sheet Building_Summary
B1: Whole-building Weighted Summary (by hybrid %)
B2: Enter each zone area; structure share = Σ(area×system%); carbon/circularity blended by each zone's three system %.
B4: Carbon intensity kgCO₂e/m² | K4: Building KPI
B5: Skin | C5: 150 | K5: Total area m² | L5: =SUM(D11:D36) -> 64800
B6: Foam | C6: 119 | K6: Skin share | L6: =SUMPRODUCT(D11:D36,F11:F36)/L5 -> 0.36120618
B7: Internal | C7: 200 | K7: Foam share | L7: =SUMPRODUCT(D11:D36,G11:G36)/L5 -> 0.36328318
K8: Internal share | L8: =SUMPRODUCT(D11:D36,H11:H36)/L5 -> 0.27551064
K9: Weighted circularity | L9: =SUMPRODUCT(D11:D36,I11:I36)/L5 -> 68.67663
B10: Zone | C10: Primary | D10: Area m² | E10: Skin% | F10: Foam% | G10: Intl% | H10: Circ(blend) | I10: Carbon(blend) | K10: Carbon kg/m² | L10: =SUM(J11:J36)/L5 -> 152.51375
B11: =Allocation!B5 -> Retail Lo Perim | C11: =Allocation!AF5 -> Foam | D11: 2500 | F11: =Allocation!AC5 -> 0.29528698 | G11: =Allocation!AD5 -> 0.56466576 | H11: =Allocation!AE5 -> 0.14004726 | I11: =F11*Allocation!$J$2+G11*Allocation!$K$2+H11*Allocation!$L$2 -> 76.809131 | J11: =D11*(F11*$C$5+G11*$C$6+H11*$C$7) -> 348744.31 | K11: Total carbon (t) | L11: =SUM(J11:J36)/1000 -> 9882.8912
B12: =Allocation!B6 -> Retail Lo Core | C12: =Allocation!AF6 -> Internal | D12: 2000 | F12: =Allocation!AC6 -> 0.073262412 | G12: =Allocation!AD6 -> 0.26966291 | H12: =Allocation!AE6 -> 0.65707468 | I12: =F12*Allocation!$J$2+G12*Allocation!$K$2+H12*Allocation!$L$2 -> 48.966491 | J12: =D12*(F12*$C$5+G12*$C$6+H12*$C$7) -> 348988.37
B13: =Allocation!B7 -> Lobby Lo | C13: =Allocation!AF7 -> Foam | D13: 1200 | F13: =Allocation!AC7 -> 0.26708049 | G13: =Allocation!AD7 -> 0.41228281 | H13: =Allocation!AE7 -> 0.3206367 | I13: =F13*Allocation!$J$2+G13*Allocation!$K$2+H13*Allocation!$L$2 -> 66.751074 | J13: =D13*(F13*$C$5+G13*$C$6+H13*$C$7) -> 183901.28
B14: =Allocation!B8 -> Parking Lo | C14: =Allocation!AF8 -> Foam | D14: 5000 | F14: =Allocation!AC8 -> 0.18215181 | G14: =Allocation!AD8 -> 0.6334675 | H14: =Allocation!AE8 -> 0.18438069 | I14: =F14*Allocation!$J$2+G14*Allocation!$K$2+H14*Allocation!$L$2 -> 75.056871 | J14: =D14*(F14*$C$5+G14*$C$6+H14*$C$7) -> 697907.71
B15: =Allocation!B9 -> Conference Lo | C15: =Allocation!AF9 -> Foam | D15: 1500 | F15: =Allocation!AC9 -> 0.18884698 | G15: =Allocation!AD9 -> 0.42847763 | H15: =Allocation!AE9 -> 0.38267538 | I15: =F15*Allocation!$J$2+G15*Allocation!$K$2+H15*Allocation!$L$2 -> 63.758455 | J15: =D15*(F15*$C$5+G15*$C$6+H15*$C$7) -> 233776.44
B16: =Allocation!B10 -> DataCenter Lo | C16: =Allocation!AF10 -> Internal | D16: 1500 | F16: =Allocation!AC10 -> 0.11599299 | G16: =Allocation!AD10 -> 0.15729537 | H16: =Allocation!AE10 -> 0.72671164 | I16: =F16*Allocation!$J$2+G16*Allocation!$K$2+H16*Allocation!$L$2 -> 44.726162 | J16: =D16*(F16*$C$5+G16*$C$6+H16*$C$7) -> 272189.14
B17: =Allocation!B11 -> Office Mid S-Perim | C17: =Allocation!AF11 -> Skin | D17: 3000 | F17: =Allocation!AC11 -> 0.61981577 | G17: =Allocation!AD11 -> 0.33646186 | H17: =Allocation!AE11 -> 0.043722367 | I17: =F17*Allocation!$J$2+G17*Allocation!$K$2+H17*Allocation!$L$2 -> 80.084999 | J17: =D17*(F17*$C$5+G17*$C$6+H17*$C$7) -> 425267.4
B18: =Allocation!B12 -> Office Mid Core | C18: =Allocation!AF12 -> Internal | D18: 1500 | F18: =Allocation!AC12 -> 0.34307737 | G18: =Allocation!AD12 -> 0.24618444 | H18: =Allocation!AE12 -> 0.41073819 | I18: =F18*Allocation!$J$2+G18*Allocation!$K$2+H18*Allocation!$L$2 -> 61.124836 | J18: =D18*(F18*$C$5+G18*$C$6+H18*$C$7) -> 244357.79
B19: =Allocation!B13 -> Office Mid N-Perim | C19: =Allocation!AF13 -> Foam | D19: 3000 | F19: =Allocation!AC13 -> 0.30964269 | G19: =Allocation!AD13 -> 0.61046423 | H19: =Allocation!AE13 -> 0.079893084 | I19: =F19*Allocation!$J$2+G19*Allocation!$K$2+H19*Allocation!$L$2 -> 80.125979 | J19: =D19*(F19*$C$5+G19*$C$6+H19*$C$7) -> 405210.79
B20: =Allocation!B14 -> Hotel Mid Perim | C20: =Allocation!AF14 -> Foam | D20: 5000 | F20: =Allocation!AC14 -> 0.34910689 | G20: =Allocation!AD14 -> 0.58164256 | H20: =Allocation!AE14 -> 0.069250551 | I20: =F20*Allocation!$J$2+G20*Allocation!$K$2+H20*Allocation!$L$2 -> 80.46356 | J20: =D20*(F20*$C$5+G20*$C$6+H20*$C$7) -> 677158.04
B21: =Allocation!B15 -> Lab Mid | C21: =Allocation!AF15 -> Internal | D21: 2500 | F21: =Allocation!AC15 -> 0.21788936 | G21: =Allocation!AD15 -> 0.25199774 | H21: =Allocation!AE15 -> 0.5301129 | I21: =F21*Allocation!$J$2+G21*Allocation!$K$2+H21*Allocation!$L$2 -> 55.19534 | J21: =D21*(F21*$C$5+G21*$C$6+H21*$C$7) -> 421734.29
B22: =Allocation!B16 -> Office Hi S-Perim | C22: =Allocation!AF16 -> Skin | D22: 4000 | F22: =Allocation!AC16 -> 0.80946826 | G22: =Allocation!AD16 -> 0.11129343 | H22: =Allocation!AE16 -> 0.079238309 | I22: =F22*Allocation!$J$2+G22*Allocation!$K$2+H22*Allocation!$L$2 -> 76.789315 | J22: =D22*(F22*$C$5+G22*$C$6+H22*$C$7) -> 602047.28
B23: =Allocation!B17 -> Office Hi Core | C23: =Allocation!AF17 -> Internal | D23: 2000 | F23: =Allocation!AC17 -> 0.34307737 | G23: =Allocation!AD17 -> 0.24618444 | H23: =Allocation!AE17 -> 0.41073819 | I23: =F23*Allocation!$J$2+G23*Allocation!$K$2+H23*Allocation!$L$2 -> 61.124836 | J23: =D23*(F23*$C$5+G23*$C$6+H23*$C$7) -> 325810.38
... B36: =Allocation!B30 -> Healthcare Mid | C36: =Allocation!AF30 -> Foam | D36: 3000 | F36: =Allocation!AC30 -> 0.34751614 | G36: =Allocation!AD30 -> 0.36889611 | H36: =Allocation!AE30 -> 0.28358776 | I36: =F36*Allocation!$J$2+G36*Allocation!$K$2+H36*Allocation!$L$2 -> 68.310661 | J36: =D36*(F36*$C$5+G36*$C$6+H36*$C$7) -> 458230.83

Sheet Transition_Engine
B1: L5.5 Structure Transition Zone Engine
B2: Detect adjacent zones → four difference scores (Structure 0.4 / Geometry 0.2 / Material 0.2 / LoadPath 0.2) → TCS 0–100 → class → recommended transition member → carbon/cost/schedule penalty.
B4: TCS weights: | C4: Struct | D4: 0.4 | E4: Geom | F4: 0.2 | G4: Mat | H4: 0.2 | I4: LoadPath | J4: 0.2 | L4: Σ | M4: =D4+F4+H4+J4 -> 1
B5: Penalty intensity (at TCS=100): | C5: Carbon kg/m² | D5: 30 | E5: Cost % | F5: 8 | G5: Schedule wk | H5: 8
B7: ① Structure diff | G7: ② Geometry diff | L7: ③ Material diff | Q7: ④ Load-path diff
B8: A\B | C8: Skin | D8: Foam | E8: Internal | G8: A\B | H8: Skin | I8: Foam | J8: Internal | L8: A\B | M8: Skin | N8: Foam | O8: Internal | Q8: A\B | R8: Skin | S8: Foam | T8: Internal
B9: Skin | C9: 0 | D9: 4 | E9: 5 | G9: Skin | H9: 2 | I9: 5 | J9: 4 | L9: Skin | M9: 0 | N9: 3 | O9: 2 | Q9: Skin | R9: 0 | S9: 4 | T9: 5
B10: Foam | C10: 4 | D10: 0 | E10: 3 | G10: Foam | H10: 5 | I10: 2 | J10: 4 | L10: Foam | M10: 3 | N10: 0 | O10: 5 | Q10: Foam | R10: 4 | S10: 0 | T10: 5
B11: Internal | C11: 5 | D11: 3 | E11: 0 | G11: Internal | H11: 4 | I11: 4 | J11: 0 | L11: Internal | M11: 2 | N11: 5 | O11: 0 | Q11: Internal | R11: 5 | S11: 5 | T11: 0
B13: A zone (upper) | C13: B zone (lower) | D13: Prim A | E13: Prim B | F13: Str | G13: Geo | H13: Mat | I13: Load | J13: TCS | K13: Class | L13: Recommended transition member | M13: Carb+ | N13: Cost+% | O13: Sched+wk
B14: Office Mid S-Perim | C14: Retail Lo Perim | D14: =INDEX(Allocation!$AF$5:$AF$30,MATCH(B14,Allocation!$B$5:$B$30,0)) -> Skin | E14: =INDEX(Allocation!$AF$5:$AF$30,MATCH(C14,Allocation!$B$5:$B$30,0)) -> Foam | F14: =INDEX($C$9:$E$11,MATCH(D14,$B$9:$B$11,0),MATCH(E14,$C$8:$E$8,0)) -> 4 | G14: =INDEX($H$9:$J$11,MATCH(D14,$G$9:$G$11,0),MATCH(E14,$H$8:$J$8,0)) -> 5 | H14: =INDEX($M$9:$O$11,MATCH(D14,$L$9:$L$11,0),MATCH(E14,$M$8:$O$8,0)) -> 3 | I14: =INDEX($R$9:$T$11,MATCH(D14,$Q$9:$Q$11,0),MATCH(E14,$R$8:$T$8,0)) -> 4 | J14: =($D$4*F14+$F$4*G14+$H$4*H14+$J$4*I14)*20 -> 80 | K14: =IF(J14<20,"Seamless",IF(J14<40,"Minor",IF(J14<60,"Moderate",IF(J14<80,"Complex","Critical")))) -> Critical | L14: =IF(D14=E14,"Continuous (no transfer)",IF(OR(AND(D14="Internal",E14="Foam"),AND(D14="Foam",E14="Internal")),"Transfer Slab / Beam / Mega Beam",IF(OR(AND(D14="Internal",E14="Skin"),AND(D14="Skin",E14="Internal")),"Belt Truss / Outrigger / Transfer Floor","Hybrid Node / Space-frame Connector / Diagrid Connector"))) -> Hybrid Node / Space-frame Connector / Diagrid Connector | M14: =J14/100*$D$5 -> 24 | N14: =J14/100*$F$5 -> 6.4 | O14: =J14/100*$H$5 -> 6.4
B15: Office Mid Core | C15: Retail Lo Core | D15: =INDEX(Allocation!$AF$5:$AF$30,MATCH(B15,Allocation!$B$5:$B$30,0)) -> Internal | E15: =INDEX(Allocation!$AF$5:$AF$30,MATCH(C15,Allocation!$B$5:$B$30,0)) -> Internal | F15: =INDEX($C$9:$E$11,MATCH(D15,$B$9:$B$11,0),MATCH(E15,$C$8:$E$8,0)) -> 0 | G15: =INDEX($H$9:$J$11,MATCH(D15,$G$9:$G$11,0),MATCH(E15,$H$8:$J$8,0)) -> 0 | H15: =INDEX($M$9:$O$11,MATCH(D15,$L$9:$L$11,0),MATCH(E15,$M$8:$O$8,0)) -> 0 | I15: =INDEX($R$9:$T$11,MATCH(D15,$Q$9:$Q$11,0),MATCH(E15,$R$8:$T$8,0)) -> 0 | J15: =($D$4*F15+$F$4*G15+$H$4*H15+$J$4*I15)*20 -> 0 | K15: =IF(J15<20,"Seamless",IF(J15<40,"Minor",IF(J15<60,"Moderate",IF(J15<80,"Complex","Critical")))) -> Seamless | L15: =IF(D15=E15,"Continuous (no transfer)",IF(OR(AND(D15="Internal",E15="Foam"),AND(D15="Foam",E15="Internal")),"Transfer Slab / Beam / Mega Beam",IF(OR(AND(D15="Internal",E15="Skin"),AND(D15="Skin",E15="Internal")),"Belt Truss / Outrigger / Transfer Floor","Hybrid Node / Space-frame Connector / Diagrid Connector"))) -> Continuous (no transfer) | M15: =J15/100*$D$5 -> 0 | N15: =J15/100*$F$5 -> 0 | O15: =J15/100*$H$5 -> 0
B16: Office Hi Core | C16: Office Mid Core | D16: =INDEX(Allocation!$AF$5:$AF$30,MATCH(B16,Allocation!$B$5:$B$30,0)) -> Internal | E16: =INDEX(Allocation!$AF$5:$AF$30,MATCH(C16,Allocation!$B$5:$B$30,0)) -> Internal | F16: =INDEX($C$9:$E$11,MATCH(D16,$B$9:$B$11,0),MATCH(E16,$C$8:$E$8,0)) -> 0 | G16: =INDEX($H$9:$J$11,MATCH(D16,$G$9:$G$11,0),MATCH(E16,$H$8:$J$8,0)) -> 0 | H16: =INDEX($M$9:$O$11,MATCH(D16,$L$9:$L$11,0),MATCH(E16,$M$8:$O$8,0)) -> 0 | I16: =INDEX($R$9:$T$11,MATCH(D16,$Q$9:$Q$11,0),MATCH(E16,$R$8:$T$8,0)) -> 0 | J16: =($D$4*F16+$F$4*G16+$H$4*H16+$J$4*I16)*20 -> 0 | K16: =IF(J16<20,"Seamless",IF(J16<40,"Minor",IF(J16<60,"Moderate",IF(J16<80,"Complex","Critical")))) -> Seamless | L16: =IF(D16=E16,"Continuous (no transfer)",IF(OR(AND(D16="Internal",E16="Foam"),AND(D16="Foam",E16="Internal")),"Transfer Slab / Beam / Mega Beam",IF(OR(AND(D16="Internal",E16="Skin"),AND(D16="Skin",E16="Internal")),"Belt Truss / Outrigger / Transfer Floor","Hybrid Node / Space-frame Connector / Diagrid Connector"))) -> Continuous (no transfer) | M16: =J16/100*$D$5 -> 0 | N16: =J16/100*$F$5 -> 0 | O16: =J16/100*$H$5 -> 0
B17: Office Super Core | C17: Office Hi Core | D17: =INDEX(Allocation!$AF$5:$AF$30,MATCH(B17,Allocation!$B$5:$B$30,0)) -> Internal | E17: =INDEX(Allocation!$AF$5:$AF$30,MATCH(C17,Allocation!$B$5:$B$30,0)) -> Internal | F17: =INDEX($C$9:$E$11,MATCH(D17,$B$9:$B$11,0),MATCH(E17,$C$8:$E$8,0)) -> 0 | G17: =INDEX($H$9:$J$11,MATCH(D17,$G$9:$G$11,0),MATCH(E17,$H$8:$J$8,0)) -> 0 | H17: =INDEX($M$9:$O$11,MATCH(D17,$L$9:$L$11,0),MATCH(E17,$M$8:$O$8,0)) -> 0 | I17: =INDEX($R$9:$T$11,MATCH(D17,$Q$9:$Q$11,0),MATCH(E17,$R$8:$T$8,0)) -> 0 | J17: =($D$4*F17+$F$4*G17+$H$4*H17+$J$4*I17)*20 -> 0 | K17: =IF(J17<20,"Seamless",IF(J17<40,"Minor",IF(J17<60,"Moderate",IF(J17<80,"Complex","Critical")))) -> Seamless | L17: =IF(D17=E17,"Continuous (no transfer)",IF(OR(AND(D17="Internal",E17="Foam"),AND(D17="Foam",E17="Internal")),"Transfer Slab / Beam / Mega Beam",IF(OR(AND(D17="Internal",E17="Skin"),AND(D17="Skin",E17="Internal")),"Belt Truss / Outrigger / Transfer Floor","Hybrid Node / Space-frame Connector / Diagrid Connector"))) -> Continuous (no transfer) | M17: =J17/100*$D$5 -> 0 | N17: =J17/100*$F$5 -> 0 | O17: =J17/100*$H$5 -> 0
B18: Office Hi S-Perim | C18: Core Spine Full | D18: =INDEX(Allocation!$AF$5:$AF$30,MATCH(B18,Allocation!$B$5:$B$30,0)) -> Skin | E18: =INDEX(Allocation!$AF$5:$AF$30,MATCH(C18,Allocation!$B$5:$B$30,0)) -> Internal | F18: =INDEX($C$9:$E$11,MATCH(D18,$B$9:$B$11,0),MATCH(E18,$C$8:$E$8,0)) -> 5 | G18: =INDEX($H$9:$J$11,MATCH(D18,$G$9:$G$11,0),MATCH(E18,$H$8:$J$8,0)) -> 4 | H18: =INDEX($M$9:$O$11,MATCH(D18,$L$9:$L$11,0),MATCH(E18,$M$8:$O$8,0)) -> 2 | I18: =INDEX($R$9:$T$11,MATCH(D18,$Q$9:$Q$11,0),MATCH(E18,$R$8:$T$8,0)) -> 5 | J18: =($D$4*F18+$F$4*G18+$H$4*H18+$J$4*I18)*20 -> 84 | K18: =IF(J18<20,"Seamless",IF(J18<40,"Minor",IF(J18<60,"Moderate",IF(J18<80,"Complex","Critical")))) -> Critical | L18: =IF(D18=E18,"Continuous (no transfer)",IF(OR(AND(D18="Internal",E18="Foam"),AND(D18="Foam",E18="Internal")),"Transfer Slab / Beam / Mega Beam",IF(OR(AND(D18="Internal",E18="Skin"),AND(D18="Skin",E18="Internal")),"Belt Truss / Outrigger / Transfer Floor","Hybrid Node / Space-frame Connector / Diagrid Connector"))) -> Belt Truss / Outrigger / Transfer Floor | M18: =J18/100*$D$5 -> 25.2 | N18: =J18/100*$F$5 -> 6.72 | O18: =J18/100*$H$5 -> 6.72
B19: Office Hi S-Perim | C19: Office Hi Core | D19: =INDEX(Allocation!$AF$5:$AF$30,MATCH(B19,Allocation!$B$5:$B$30,0)) -> Skin | E19: =INDEX(Allocation!$AF$5:$AF$30,MATCH(C19,Allocation!$B$5:$B$30,0)) -> Internal | F19: =INDEX($C$9:$E$11,MATCH(D19,$B$9:$B$11,0),MATCH(E19,$C$8:$E$8,0)) -> 5 | G19: =INDEX($H$9:$J$11,MATCH(D19,$G$9:$G$11,0),MATCH(E19,$H$8:$J$8,0)) -> 4 | H19: =INDEX($M$9:$O$11,MATCH(D19,$L$9:$L$11,0),MATCH(E19,$M$8:$O$8,0)) -> 2 | I19: =INDEX($R$9:$T$11,MATCH(D19,$Q$9:$Q$11,0),MATCH(E19,$R$8:$T$8,0)) -> 5 | J19: =($D$4*F19+$F$4*G19+$H$4*H19+$J$4*I19)*20 -> 84 | K19: =IF(J19<20,"Seamless",IF(J19<40,"Minor",IF(J19<60,"Moderate",IF(J19<80,"Complex","Critical")))) -> Critical | L19: =IF(D19=E19,"Continuous (no transfer)",IF(OR(AND(D19="Internal",E19="Foam"),AND(D19="Foam",E19="Internal")),"Transfer Slab / Beam / Mega Beam",IF(OR(AND(D19="Internal",E19="Skin"),AND(D19="Skin",E19="Internal")),"Belt Truss / Outrigger / Transfer Floor","Hybrid Node / Space-frame Connector / Diagrid Connector"))) -> Belt Truss / Outrigger / Transfer Floor | M19: =J19/100*$D$5 -> 25.2 | N19: =J19/100*$F$5 -> 6.72 | O19: =J19/100*$H$5 -> 6.72
B20: Resid Hi Core | C20: Office Hi Core | D20: =INDEX(Allocation!$AF$5:$AF$30,MATCH(B20,Allocation!$B$5:$B$30,0)) -> Skin | E20: =INDEX(Allocation!$AF$5:$AF$30,MATCH(C20,Allocation!$B$5:$B$30,0)) -> Internal | F20: =INDEX($C$9:$E$11,MATCH(D20,$B$9:$B$11,0),MATCH(E20,$C$8:$E$8,0)) -> 5 | G20: =INDEX($H$9:$J$11,MATCH(D20,$G$9:$G$11,0),MATCH(E20,$H$8:$J$8,0)) -> 4 | H20: =INDEX($M$9:$O$11,MATCH(D20,$L$9:$L$11,0),MATCH(E20,$M$8:$O$8,0)) -> 2 | I20: =INDEX($R$9:$T$11,MATCH(D20,$Q$9:$Q$11,0),MATCH(E20,$R$8:$T$8,0)) -> 5 | J20: =($D$4*F20+$F$4*G20+$H$4*H20+$J$4*I20)*20 -> 84 | K20: =IF(J20<20,"Seamless",IF(J20<40,"Minor",IF(J20<60,"Moderate",IF(J20<80,"Complex","Critical")))) -> Critical | L20: =IF(D20=E20,"Continuous (no transfer)",IF(OR(AND(D20="Internal",E20="Foam"),AND(D20="Foam",E20="Internal")),"Transfer Slab / Beam / Mega Beam",IF(OR(AND(D20="Internal",E20="Skin"),AND(D20="Skin",E20="Internal")),"Belt Truss / Outrigger / Transfer Floor","Hybrid Node / Space-frame Connector / Diagrid Connector"))) -> Belt Truss / Outrigger / Transfer Floor | M20: =J20/100*$D$5 -> 25.2 | N20: =J20/100*$F$5 -> 6.72 | O20: =J20/100*$H$5 -> 6.72
B21: SkyLobby Hi | C21: Office Hi S-Perim | D21: =INDEX(Allocation!$AF$5:$AF$30,MATCH(B21,Allocation!$B$5:$B$30,0)) -> Foam | E21: =INDEX(Allocation!$AF$5:$AF$30,MATCH(C21,Allocation!$B$5:$B$30,0)) -> Skin | F21: =INDEX($C$9:$E$11,MATCH(D21,$B$9:$B$11,0),MATCH(E21,$C$8:$E$8,0)) -> 4 | G21: =INDEX($H$9:$J$11,MATCH(D21,$G$9:$G$11,0),MATCH(E21,$H$8:$J$8,0)) -> 5 | H21: =INDEX($M$9:$O$11,MATCH(D21,$L$9:$L$11,0),MATCH(E21,$M$8:$O$8,0)) -> 3 | I21: =INDEX($R$9:$T$11,MATCH(D21,$Q$9:$Q$11,0),MATCH(E21,$R$8:$T$8,0)) -> 4 | J21: =($D$4*F21+$F$4*G21+$H$4*H21+$J$4*I21)*20 -> 80 | K21: =IF(J21<20,"Seamless",IF(J21<40,"Minor",IF(J21<60,"Moderate",IF(J21<80,"Complex","Critical")))) -> Critical | L21: =IF(D21=E21,"Continuous (no transfer)",IF(OR(AND(D21="Internal",E21="Foam"),AND(D21="Foam",E21="Internal")),"Transfer Slab / Beam / Mega Beam",IF(OR(AND(D21="Internal",E21="Skin"),AND(D21="Skin",E21="Internal")),"Belt Truss / Outrigger / Transfer Floor","Hybrid Node / Space-frame Connector / Diagrid Connector"))) -> Hybrid Node / Space-frame Connector / Diagrid Connector | M21: =J21/100*$D$5 -> 24 | N21: =J21/100*$F$5 -> 6.4 | O21: =J21/100*$H$5 -> 6.4
B24: Step 9 Penalty fed back to optimization: Final = 0.5×Fitness + 0.3×Circularity − 0.2×TransitionPenalty
B25: Zone | C25: Primary | D25: Fitness×Mult | E25: Circ | F25: Transition penalty (max TCS) | G25: Adjusted final | H25: Verdict
B26: =Allocation!B5 -> Retail Lo Perim | C26: =Allocation!AF5 -> Foam | D26: =IF(Allocation!AF5="Skin",Allocation!T5*Allocation!W5,IF(Allocation!AF5="Foam",Allocation!U5*Allocation!X5,Allocation!V5*Allocation!Y5)) -> 71.612903 | E26: =IF(Allocation!AF5="Skin",Allocation!$J$2,IF(Allocation!AF5="Foam",Allocation!$K$2,Allocation!$L$2)) -> 86.75 | F26: =SUMPRODUCT(MAX((($B$14:$B$21=Allocation!B5)+($C$14:$C$21=Allocation!B5))*$J$14:$J$21)) -> 80 | G26: =0.5*D26+0.3*E26-0.2*F26 -> 45.831452 | H26: =IF(F26>=60,IF(Allocation!AH5<0.15,"⚠ High transition + weak lead → align to neighbour","⚠ High transition → needs transfer member"),IF(F26>=40,"△ Moderate transition","✓ Acceptable")) -> ⚠ High transition → needs transfer member
B27: =Allocation!B6 -> Retail Lo Core | C27: =Allocation!AF6 -> Internal | D27: =IF(Allocation!AF6="Skin",Allocation!T6*Allocation!W6,IF(Allocation!AF6="Foam",Allocation!U6*Allocation!X6,Allocation!V6*Allocation!Y6)) -> 109.16667 | E27: =IF(Allocation!AF6="Skin",Allocation!$J$2,IF(Allocation!AF6="Foam",Allocation!$K$2,Allocation!$L$2)) -> 30 | F27: =SUMPRODUCT(MAX((($B$14:$B$21=Allocation!B6)+($C$14:$C$21=Allocation!B6))*$J$14:$J$21)) -> 0 | G27: =0.5*D27+0.3*E27-0.2*F27 -> 63.583333 | H27: =IF(F27>=60,IF(Allocation!AH6<0.15,"⚠ High transition + weak lead → align to neighbour","⚠ High transition → needs transfer member"),IF(F27>=40,"△ Moderate transition","✓ Acceptable")) -> ✓ Acceptable
B28: =Allocation!B7 -> Lobby Lo | C28: =Allocation!AF7 -> Foam | D28: =IF(Allocation!AF7="Skin",Allocation!T7*Allocation!W7,IF(Allocation!AF7="Foam",Allocation!U7*Allocation!X7,Allocation!V7*Allocation!Y7)) -> 68.965517 | E28: =IF(Allocation!AF7="Skin",Allocation!$J$2,IF(Allocation!AF7="Foam",Allocation!$K$2,Allocation!$L$2)) -> 86.75 | F28: =SUMPRODUCT(MAX((($B$14:$B$21=Allocation!B7)+($C$14:$C$21=Allocation!B7))*$J$14:$J$21)) -> 0 | G28: =0.5*D28+0.3*E28-0.2*F28 -> 60.507759 | H28: =IF(F28>=60,IF(Allocation!AH7<0.15,"⚠ High transition + weak lead → align to neighbour","⚠ High transition → needs transfer member"),IF(F28>=40,"△ Moderate transition","✓ Acceptable")) -> ✓ Acceptable
B29: =Allocation!B8 -> Parking Lo | C29: =Allocation!AF8 -> Foam | D29: =IF(Allocation!AF8="Skin",Allocation!T8*Allocation!W8,IF(Allocation!AF8="Foam",Allocation!U8*Allocation!X8,Allocation!V8*Allocation!Y8)) -> 78.378378 | E29: =IF(Allocation!AF8="Skin",Allocation!$J$2,IF(Allocation!AF8="Foam",Allocation!$K$2,Allocation!$L$2)) -> 86.75 | F29: =SUMPRODUCT(MAX((($B$14:$B$21=Allocation!B8)+($C$14:$C$21=Allocation!B8))*$J$14:$J$21)) -> 0 | G29: =0.5*D29+0.3*E29-0.2*F29 -> 65.214189 | H29: =IF(F29>=60,IF(Allocation!AH8<0.15,"⚠ High transition + weak lead → align to neighbour","⚠ High transition → needs transfer member"),IF(F29>=40,"△ Moderate transition","✓ Acceptable")) -> ✓ Acceptable
B30: =Allocation!B9 -> Conference Lo | C30: =Allocation!AF9 -> Foam | D30: =IF(Allocation!AF9="Skin",Allocation!T9*Allocation!W9,IF(Allocation!AF9="Foam",Allocation!U9*Allocation!X9,Allocation!V9*Allocation!Y9)) -> 72.352941 | E30: =IF(Allocation!AF9="Skin",Allocation!$J$2,IF(Allocation!AF9="Foam",Allocation!$K$2,Allocation!$L$2)) -> 86.75 | F30: =SUMPRODUCT(MAX((($B$14:$B$21=Allocation!B9)+($C$14:$C$21=Allocation!B9))*$J$14:$J$21)) -> 0 | G30: =0.5*D30+0.3*E30-0.2*F30 -> 62.201471 | H30: =IF(F30>=60,IF(Allocation!AH9<0.15,"⚠ High transition + weak lead → align to neighbour","⚠ High transition → needs transfer member"),IF(F30>=40,"△ Moderate transition","✓ Acceptable")) -> ✓ Acceptable
B31: =Allocation!B10 -> DataCenter Lo | C31: =Allocation!AF10 -> Internal | D31: =IF(Allocation!AF10="Skin",Allocation!T10*Allocation!W10,IF(Allocation!AF10="Foam",Allocation!U10*Allocation!X10,Allocation!V10*Allocation!Y10)) -> 105.34118 | E31: =IF(Allocation!AF10="Skin",Allocation!$J$2,IF(Allocation!AF10="Foam",Allocation!$K$2,Allocation!$L$2)) -> 30 | F31: =SUMPRODUCT(MAX((($B$14:$B$21=Allocation!B10)+($C$14:$C$21=Allocation!B10))*$J$14:$J$21)) -> 0 | G31: =0.5*D31+0.3*E31-0.2*F31 -> 61.670588 | H31: =IF(F31>=60,IF(Allocation!AH10<0.15,"⚠ High transition + weak lead → align to neighbour","⚠ High transition → needs transfer member"),IF(F31>=40,"△ Moderate transition","✓ Acceptable")) -> ✓ Acceptable
B32: =Allocation!B11 -> Office Mid S-Perim | C32: =Allocation!AF11 -> Skin | D32: =IF(Allocation!AF11="Skin",Allocation!T11*Allocation!W11,IF(Allocation!AF11="Foam",Allocation!U11*Allocation!X11,Allocation!V11*Allocation!Y11)) -> 83.375 | E32: =IF(Allocation!AF11="Skin",Allocation!$J$2,IF(Allocation!AF11="Foam",Allocation!$K$2,Allocation!$L$2)) -> 80 | F32: =SUMPRODUCT(MAX((($B$14:$B$21=Allocation!B11)+($C$14:$C$21=Allocation!B11))*$J$14:$J$21)) -> 80 | G32: =0.5*D32+0.3*E32-0.2*F32 -> 49.6875 | H32: =IF(F32>=60,IF(Allocation!AH11<0.15,"⚠ High transition + weak lead → align to neighbour","⚠ High transition → needs transfer member"),IF(F32>=40,"△ Moderate transition","✓ Acceptable")) -> ⚠ High transition → needs transfer member
B33: =Allocation!B12 -> Office Mid Core | C33: =Allocation!AF12 -> Internal | D33: =IF(Allocation!AF12="Skin",Allocation!T12*Allocation!W12,IF(Allocation!AF12="Foam",Allocation!U12*Allocation!X12,Allocation!V12*Allocation!Y12)) -> 94.285714 | E33: =IF(Allocation!AF12="Skin",Allocation!$J$2,IF(Allocation!AF12="Foam",Allocation!$K$2,Allocation!$L$2)) -> 30 | F33: =SUMPRODUCT(MAX((($B$14:$B$21=Allocation!B12)+($C$14:$C$21=Allocation!B12))*$J$14:$J$21)) -> 0 | G33: =0.5*D33+0.3*E33-0.2*F33 -> 56.142857 | H33: =IF(F33>=60,IF(Allocation!AH12<0.15,"⚠ High transition + weak lead → align to neighbour","⚠ High transition → needs transfer member"),IF(F33>=40,"△ Moderate transition","✓ Acceptable")) -> ✓ Acceptable
B34: =Allocation!B13 -> Office Mid N-Perim | C34: =Allocation!AF13 -> Foam | D34: =IF(Allocation!AF13="Skin",Allocation!T13*Allocation!W13,IF(Allocation!AF13="Foam",Allocation!U13*Allocation!X13,Allocation!V13*Allocation!Y13)) -> 75.675676 | E34: =IF(Allocation!AF13="Skin",Allocation!$J$2,IF(Allocation!AF13="Foam",Allocation!$K$2,Allocation!$L$2)) -> 86.75 | F34: =SUMPRODUCT(MAX((($B$14:$B$21=Allocation!B13)+($C$14:$C$21=Allocation!B13))*$J$14:$J$21)) -> 0 | G34: =0.5*D34+0.3*E34-0.2*F34 -> 63.862838 | H34: =IF(F34>=60,IF(Allocation!AH13<0.15,"⚠ High transition + weak lead → align to neighbour","⚠ High transition → needs transfer member"),IF(F34>=40,"△ Moderate transition","✓ Acceptable")) -> ✓ Acceptable
B35: =Allocation!B14 -> Hotel Mid Perim | C35: =Allocation!AF14 -> Foam | D35: =IF(Allocation!AF14="Skin",Allocation!T14*Allocation!W14,IF(Allocation!AF14="Foam",Allocation!U14*Allocation!X14,Allocation!V14*Allocation!Y14)) -> 75.882353 | E35: =IF(Allocation!AF14="Skin",Allocation!$J$2,IF(Allocation!AF14="Foam",Allocation!$K$2,Allocation!$L$2)) -> 86.75 | F35: =SUMPRODUCT(MAX((($B$14:$B$21=Allocation!B14)+($C$14:$C$21=Allocation!B14))*$J$14:$J$21)) -> 0 | G35: =0.5*D35+0.3*E35-0.2*F35 -> 63.966176 | H35: =IF(F35>=60,IF(Allocation!AH14<0.15,"⚠ High transition + weak lead → align to neighbour","⚠ High transition → needs transfer member"),IF(F35>=40,"△ Moderate transition","✓ Acceptable")) -> ✓ Acceptable
B36: =Allocation!B15 -> Lab Mid | C36: =Allocation!AF15 -> Internal | D36: =IF(Allocation!AF15="Skin",Allocation!T15*Allocation!W15,IF(Allocation!AF15="Foam",Allocation!U15*Allocation!X15,Allocation!V15*Allocation!Y15)) -> 99.282051 | E36: =IF(Allocation!AF15="Skin",Allocation!$J$2,IF(Allocation!AF15="Foam",Allocation!$K$2,Allocation!$L$2)) -> 30 | F36: =SUMPRODUCT(MAX((($B$14:$B$21=Allocation!B15)+($C$14:$C$21=Allocation!B15))*$J$14:$J$21)) -> 0 | G36: =0.5*D36+0.3*E36-0.2*F36 -> 58.641026 | H36: =IF(F36>=60,IF(Allocation!AH15<0.15,"⚠ High transition + weak lead → align to neighbour","⚠ High transition → needs transfer member"),IF(F36>=40,"△ Moderate transition","✓ Acceptable")) -> ✓ Acceptable
B37: =Allocation!B16 -> Office Hi S-Perim | C37: =Allocation!AF16 -> Skin | D37: =IF(Allocation!AF16="Skin",Allocation!T16*Allocation!W16,IF(Allocation!AF16="Foam",Allocation!U16*Allocation!X16,Allocation!V16*Allocation!Y16)) -> 87.764634 | E37: =IF(Allocation!AF16="Skin",Allocation!$J$2,IF(Allocation!AF16="Foam",Allocation!$K$2,Allocation!$L$2)) -> 80 | F37: =SUMPRODUCT(MAX((($B$14:$B$21=Allocation!B16)+($C$14:$C$21=Allocation!B16))*$J$14:$J$21)) -> 84 | G37: =0.5*D37+0.3*E37-0.2*F37 -> 51.082317 | H37: =IF(F37>=60,IF(Allocation!AH16<0.15,"⚠ High transition + weak lead → align to neighbour","⚠ High transition → needs transfer member"),IF(F37>=40,"△ Moderate transition","✓ Acceptable")) -> ⚠ High transition → needs transfer member
... B51: =Allocation!B30 -> Healthcare Mid | C51: =Allocation!AF30 -> Foam | D51: =IF(Allocation!AF30="Skin",Allocation!T30*Allocation!W30,IF(Allocation!AF30="Foam",Allocation!U30*Allocation!X30,Allocation!V30*Allocation!Y30)) -> 67.263158 | E51: =IF(Allocation!AF30="Skin",Allocation!$J$2,IF(Allocation!AF30="Foam",Allocation!$K$2,Allocation!$L$2)) -> 86.75 | F51: =SUMPRODUCT(MAX((($B$14:$B$21=Allocation!B30)+($C$14:$C$21=Allocation!B30))*$J$14:$J$21)) -> 0 | G51: =0.5*D51+0.3*E51-0.2*F51 -> 59.656579 | H51: =IF(F51>=60,IF(Allocation!AH30<0.15,"⚠ High transition + weak lead → align to neighbour","⚠ High transition → needs transfer member"),IF(F51>=40,"△ Moderate transition","✓ Acceptable")) -> ✓ Acceptable

Sheet Global_System
B1: Global Lateral vs Local Gravity
B2: A building has one primary lateral system. Decide the global lateral system first (RC core or perimeter diagrid); floor/gravity is then left to each zone's local allocation.
B4: Building height (m) | C4: 140
B5: Facade primary = Skin? | C5: =IF(INDEX(Allocation!$AF$5:$AF$30,MATCH("South Facade Hi",Allocation!$B$5:$B$30,0))="Skin","Yes","No") -> Yes
B7: ▶ Recommended global lateral system
B8: =IF($C$4>200,"RC core (Internal) primary lateral + outrigger trusses",IF(AND($C$4>=80,$C$5="Yes"),"⇒ Perimeter diagrid (Skin) can be primary lateral; RC core reduced to circulation shaft",IF($C$4>=80,"RC core (Internal) primary lateral","Frame / shear wall is sufficient"))) -> ⇒ Perimeter diagrid (Skin) can be primary lateral; RC core reduced to circulation shaft
B10: Each zone: Global lateral vs Local gravity
B11: Zone | C11: Primary allocation | D11: Role | E11: Note
B12: =Allocation!B5 -> Retail Lo Perim | C12: =Allocation!AF5 -> Foam | D12: =IF(OR(Allocation!E5="Core",Allocation!D5="Super",AND(Allocation!E5="Perim",ISNUMBER(SEARCH("Facade",Allocation!B5)))),"Global lateral","Local gravity") -> Local gravity | E12: =IF(OR(Allocation!E5="Core",Allocation!D5="Super",AND(Allocation!E5="Perim",ISNUMBER(SEARCH("Facade",Allocation!B5)))),"resists building lateral","gravity/span; lateral handled by Global") -> gravity/span; lateral handled by Global
B13: =Allocation!B6 -> Retail Lo Core | C13: =Allocation!AF6 -> Internal | D13: =IF(OR(Allocation!E6="Core",Allocation!D6="Super",AND(Allocation!E6="Perim",ISNUMBER(SEARCH("Facade",Allocation!B6)))),"Global lateral","Local gravity") -> Global lateral | E13: =IF(OR(Allocation!E6="Core",Allocation!D6="Super",AND(Allocation!E6="Perim",ISNUMBER(SEARCH("Facade",Allocation!B6)))),"resists building lateral","gravity/span; lateral handled by Global") -> resists building lateral
B14: =Allocation!B7 -> Lobby Lo | C14: =Allocation!AF7 -> Foam | D14: =IF(OR(Allocation!E7="Core",Allocation!D7="Super",AND(Allocation!E7="Perim",ISNUMBER(SEARCH("Facade",Allocation!B7)))),"Global lateral","Local gravity") -> Local gravity | E14: =IF(OR(Allocation!E7="Core",Allocation!D7="Super",AND(Allocation!E7="Perim",ISNUMBER(SEARCH("Facade",Allocation!B7)))),"resists building lateral","gravity/span; lateral handled by Global") -> gravity/span; lateral handled by Global
B15: =Allocation!B8 -> Parking Lo | C15: =Allocation!AF8 -> Foam | D15: =IF(OR(Allocation!E8="Core",Allocation!D8="Super",AND(Allocation!E8="Perim",ISNUMBER(SEARCH("Facade",Allocation!B8)))),"Global lateral","Local gravity") -> Global lateral | E15: =IF(OR(Allocation!E8="Core",Allocation!D8="Super",AND(Allocation!E8="Perim",ISNUMBER(SEARCH("Facade",Allocation!B8)))),"resists building lateral","gravity/span; lateral handled by Global") -> resists building lateral
B16: =Allocation!B9 -> Conference Lo | C16: =Allocation!AF9 -> Foam | D16: =IF(OR(Allocation!E9="Core",Allocation!D9="Super",AND(Allocation!E9="Perim",ISNUMBER(SEARCH("Facade",Allocation!B9)))),"Global lateral","Local gravity") -> Global lateral | E16: =IF(OR(Allocation!E9="Core",Allocation!D9="Super",AND(Allocation!E9="Perim",ISNUMBER(SEARCH("Facade",Allocation!B9)))),"resists building lateral","gravity/span; lateral handled by Global") -> resists building lateral
B17: =Allocation!B10 -> DataCenter Lo | C17: =Allocation!AF10 -> Internal | D17: =IF(OR(Allocation!E10="Core",Allocation!D10="Super",AND(Allocation!E10="Perim",ISNUMBER(SEARCH("Facade",Allocation!B10)))),"Global lateral","Local gravity") -> Global lateral | E17: =IF(OR(Allocation!E10="Core",Allocation!D10="Super",AND(Allocation!E10="Perim",ISNUMBER(SEARCH("Facade",Allocation!B10)))),"resists building lateral","gravity/span; lateral handled by Global") -> resists building lateral
B18: =Allocation!B11 -> Office Mid S-Perim | C18: =Allocation!AF11 -> Skin | D18: =IF(OR(Allocation!E11="Core",Allocation!D11="Super",AND(Allocation!E11="Perim",ISNUMBER(SEARCH("Facade",Allocation!B11)))),"Global lateral","Local gravity") -> Local gravity | E18: =IF(OR(Allocation!E11="Core",Allocation!D11="Super",AND(Allocation!E11="Perim",ISNUMBER(SEARCH("Facade",Allocation!B11)))),"resists building lateral","gravity/span; lateral handled by Global") -> gravity/span; lateral handled by Global
B19: =Allocation!B12 -> Office Mid Core | C19: =Allocation!AF12 -> Internal | D19: =IF(OR(Allocation!E12="Core",Allocation!D12="Super",AND(Allocation!E12="Perim",ISNUMBER(SEARCH("Facade",Allocation!B12)))),"Global lateral","Local gravity") -> Global lateral | E19: =IF(OR(Allocation!E12="Core",Allocation!D12="Super",AND(Allocation!E12="Perim",ISNUMBER(SEARCH("Facade",Allocation!B12)))),"resists building lateral","gravity/span; lateral handled by Global") -> resists building lateral
B20: =Allocation!B13 -> Office Mid N-Perim | C20: =Allocation!AF13 -> Foam | D20: =IF(OR(Allocation!E13="Core",Allocation!D13="Super",AND(Allocation!E13="Perim",ISNUMBER(SEARCH("Facade",Allocation!B13)))),"Global lateral","Local gravity") -> Local gravity | E20: =IF(OR(Allocation!E13="Core",Allocation!D13="Super",AND(Allocation!E13="Perim",ISNUMBER(SEARCH("Facade",Allocation!B13)))),"resists building lateral","gravity/span; lateral handled by Global") -> gravity/span; lateral handled by Global
B21: =Allocation!B14 -> Hotel Mid Perim | C21: =Allocation!AF14 -> Foam | D21: =IF(OR(Allocation!E14="Core",Allocation!D14="Super",AND(Allocation!E14="Perim",ISNUMBER(SEARCH("Facade",Allocation!B14)))),"Global lateral","Local gravity") -> Local gravity | E21: =IF(OR(Allocation!E14="Core",Allocation!D14="Super",AND(Allocation!E14="Perim",ISNUMBER(SEARCH("Facade",Allocation!B14)))),"resists building lateral","gravity/span; lateral handled by Global") -> gravity/span; lateral handled by Global
B22: =Allocation!B15 -> Lab Mid | C22: =Allocation!AF15 -> Internal | D22: =IF(OR(Allocation!E15="Core",Allocation!D15="Super",AND(Allocation!E15="Perim",ISNUMBER(SEARCH("Facade",Allocation!B15)))),"Global lateral","Local gravity") -> Local gravity | E22: =IF(OR(Allocation!E15="Core",Allocation!D15="Super",AND(Allocation!E15="Perim",ISNUMBER(SEARCH("Facade",Allocation!B15)))),"resists building lateral","gravity/span; lateral handled by Global") -> gravity/span; lateral handled by Global
B23: =Allocation!B16 -> Office Hi S-Perim | C23: =Allocation!AF16 -> Skin | D23: =IF(OR(Allocation!E16="Core",Allocation!D16="Super",AND(Allocation!E16="Perim",ISNUMBER(SEARCH("Facade",Allocation!B16)))),"Global lateral","Local gravity") -> Local gravity | E23: =IF(OR(Allocation!E16="Core",Allocation!D16="Super",AND(Allocation!E16="Perim",ISNUMBER(SEARCH("Facade",Allocation!B16)))),"resists building lateral","gravity/span; lateral handled by Global") -> gravity/span; lateral handled by Global
... B37: =Allocation!B30 -> Healthcare Mid | C37: =Allocation!AF30 -> Foam | D37: =IF(OR(Allocation!E30="Core",Allocation!D30="Super",AND(Allocation!E30="Perim",ISNUMBER(SEARCH("Facade",Allocation!B30)))),"Global lateral","Local gravity") -> Local gravity | E37: =IF(OR(Allocation!E30="Core",Allocation!D30="Super",AND(Allocation!E30="Perim",ISNUMBER(SEARCH("Facade",Allocation!B30)))),"resists building lateral","gravity/span; lateral handled by Global") -> gravity/span; lateral handled by Global

Sheet Sources
B2: Engineering Data Sources
B4: # | C4: Topic | D4: Key finding | E4: Source
B5: S1 | C5: Embodied carbon | D5: Timber 119 / RC 185 / Steel 228 kgCO₂e/m² (median) | E5: Hart et al. 2021
B6: S3 | C6: Steel circularity | D6: Recovery >95% but direct reuse ~7% | E6: SteelConstruction.info; BCSA
B7: S5 | C7: Diagrid | D7: ~15–20% steel saving, high lateral stiffness, super-tall cases | E7: Moon 2007; Structures Centre
B8: S7 | C8: Mass-timber fire | D8: CLT charring 2–3 hr; IBC 2021 up to 18 storeys | E8: US FPL; ThinkWood
B9: S8 | C9: Mass-timber seismic | D9: 10-storey shake table, no collapse (light + rocking walls) | E9: NHERI TallWood
B10: S9 | C10: Mass-timber height | D10: Tallest ~86 m, mostly hybrid RC core (hence >120m constraint) | E10: Skyscraper.org
